Workbook

Sheet List2
B1: Legenda: | C1: KAM | D1: Likvidace | E1: KAPU
A2: aktivní | B2: Stav | C2: Číslosmlouvy | D2: IČfirmy | E2: Názevfirmy | F2: Ulice | G2: PSČ | H2: Obec | I2: Kontaktníosoba | J2: E-mail | K2: Telefon | L2: Druh | M2: Opravujíznačkyaut | N2: Prohlídkovémísto | O2: Provoznídoba | P2: WEB | Q2: Okres | R2: Kraj | S2: GPSLat | T2: GPSLng | U2: AVNsleva | V2: CebiGlassGT | W2: AudaGlass | X2: Prvníprasklina | Y2: dalšípraskliny | Z2: Kalibracekamery | AA2: SlevananáhradnídilydleAVN | AB2: Mechanickávozidlamimoavn | AC2: Klempířskávozidlamimoavn | AD2: Mechanická | AE2: Klempířská | AF2: Lakýrnicképráce | AG2: MeachanickáHD | AH2: KlepířskáHD | AI2: LakHD | AJ2: AZT–UNIlaky | AK2: metalickéaperleťovélaky | AL2: SilverDat | AM2: DAT-Eurolak | AN2: Slevananáhradnídílyamateriál | AO2: drobnýrežijnímateriál | AP2: originálnínáhradnídílyamateriál | AQ2: aftermarketovénáhradnídílyamateriál | AR2: slevanapráci | AS2: originálnípoužiténáhradnídílyamateriál | AT2: Prohlídka | AU2: Poznámky | AV2: Limitprohlídkyod15.9.2022 | AW2: Dodávky+SUVvše
A3: Ano | B3: ACC | C3: 119/2019 | D3: 14787547 | E3: VáclavKačírek | F3: Náměstí3 | G3: 26724 | H3: Neumětely | I3: VáclavKačírek | J3: autokacirek@autokacirek.cz | K3: 7.3292109e+08 | L3: NeautorizovanýservisSAG | M3: všechnavozidla | N3: NE | O3: Po-Pá8:00-16:30 | Q3: =VLOOKUP(G3,seznampsc!A:B,2,FALSE) -> Beroun | R3: =VLOOKUP(G3,seznampsc!A:C,3,FALSE) -> Středočeský kraj | S3: 49.85208 | T3: 14.03656 | AD3: 680 | AE3: 680 | AF3: 680 | AQ3: 10 | AV3: 100000
B4: DIRECT | C4: 003/2016 | D4: 48028321 | E4: AUTOPAPOUŠEKs.r.o. | F4: Svídnická613/7 | G4: 18100 | H4: Praha8-Troja | I4: p.Vogel | J4: vogel@autopapousek.cz | K4: 608910930 | L4: NeautorizovanýservisDIRECT | M4: všechnavozidla | N4: NE | O4: 7:00-18:00|7:00-18:00|7:00-18:00|7:00-18:00|7:00-18:00|-|-. | Q4: =VLOOKUP(G4,seznampsc!A:B,2,FALSE) -> Hlavní město Praha | R4: =VLOOKUP(G4,seznampsc!A:C,3,FALSE) -> Hlavní město Praha | S4: 50.12872 | T4: 14.41488 | AU4: Vypovídámk31.3.2023smlouvu.PL
B5: DIRECT | C5: 004/2016 | D5: 17048818 | E5: FEMATs.r.o. | F5: Vrážská1562/24 | G5: 15300 | H5: Praha | I5: ZdeněkSoukup,HynekFaktor | J5: servis@femat.cz | K5: 6.0358868e+08 | L5: Osobní | M5: Škoda | N5: NE | O5: 7:00-18:00|7:00-18:00|7:00-18:00|7:00-18:00|7:00-18:00|8:00-13:00|-. | Q5: =VLOOKUP(G5,seznampsc!A:B,2,FALSE) -> Hlavní město Praha | R5: =VLOOKUP(G5,seznampsc!A:C,3,FALSE) -> Hlavní město Praha | S5: 49.989849 | T5: 14.370193 | AV5: 200000
B6: DIRECT | C6: 005/2016 | D6: 62914910 | E6: DOMANSKÝs.r.o. | F6: Českobrodská566 | G6: 19800 | H6: Praha | I6: KarelVyšinka | J6: karel.vysinka@domanský.cz | K6: 604306306 | L6: Osobní | M6: Peugeot,Citroën | N6: NE | O6: 7:00-19:00|7:00-19:00|7:00-19:00|7:00-19:00|7:00-19:00|-|-. | Q6: =VLOOKUP(G6,seznampsc!A:B,2,FALSE) -> Hlavní město Praha | R6: =VLOOKUP(G6,seznampsc!A:C,3,FALSE) -> Hlavní město Praha | S6: 50.087658 | T6: 14.556437 | AV6: 200000
B7: DIRECT | C7: 005/2016 | D7: 62914910 | E7: DOMANSKÝs.r.o. | F7: Tlumačovská1298 | G7: 15500 | H7: Praha | I7: MartinHavránek | J7: servisP5@domansky.cz | K7: 775307607 | L7: Osobní | M7: Peugeot,Citroën | N7: NE | O7: 7:00-19:00|7:00-19:00|7:00-19:00|7:00-19:00|7:00-19:00|8:00-14:00|-. | Q7: =VLOOKUP(G7,seznampsc!A:B,2,FALSE) -> Hlavní město Praha | R7: =VLOOKUP(G7,seznampsc!A:C,3,FALSE) -> Hlavní město Praha | S7: 50.03963 | T7: 14.330823 | AV7: 200000
B8: DIRECT | C8: 005/2016 | D8: 62914910 | E8: DOMANSKÝs.r.o. | F8: Zdiby195 | G8: 25066 | H8: Zdiby | I8: MartinJanek | J8: martin.janek@domansky.cz | K8: 775858857 | L8: Osobní | M8: Peugeot,Citroën,Toyota | N8: NE | O8: 7:00-19:00|7:00-19:00|7:00-19:00|7:00-19:00|7:00-19:00|8:00-14:00|-. | Q8: =VLOOKUP(G8,seznampsc!A:B,2,FALSE) -> Praha-východ | R8: =VLOOKUP(G8,seznampsc!A:C,3,FALSE) -> Středočeský kraj | S8: 50.1696486 | T8: 14.4592908 | AV8: 200000
B9: DIRECT | C9: 005/2016 | D9: 62914910 | E9: DOMANSKÝs.r.o. | F9: Herlošova2925 | G9: 39001 | H9: Tábor | I9: PetrJirsík | J9: petr.jirsik@domansky.cz | K9: 775607807 | L9: Osobní | M9: Peugeot,Citroën | N9: NE | O9: 7:00-17:00|7:00-17:00|7:00-17:00|7:00-17:00|7:00-17:00|8:00-12:00|-. | Q9: =VLOOKUP(G9,seznampsc!A:B,2,FALSE) -> Tábor | R9: =VLOOKUP(G9,seznampsc!A:C,3,FALSE) -> Jihočeský kraj | S9: 49.413788 | T9: 14.664725 | AU9: pobočkazrušená,prodejpřesunutýdoPrahy
B10: DIRECT | C10: 005/2016 | D10: 62914910 | E10: DOMANSKÝs.r.o. | F10: Skorkovská1644 | G10: 19800 | H10: Praha | I10: PetrKerhat | J10: petr.kerhat@domansky.cz | K10: 775444087 | L10: Osobní | M10: Peugeot,Citroën | N10: NE | O10: 7:00-19:00|7:00-19:00|7:00-19:00|7:00-19:00|7:00-19:00|8:00-14:00|-. | Q10: =VLOOKUP(G10,seznampsc!A:B,2,FALSE) -> Hlavní město Praha | R10: =VLOOKUP(G10,seznampsc!A:C,3,FALSE) -> Hlavní město Praha | S10: 50.110744 | T10: 14.574931 | AV10: 200000
B11: DIRECT | C11: 006/2016 | D11: 01718053 | E11: HyundaiPrahaDomanskýs.r.o. | F11: Jeremiášova1 | G11: 15500 | H11: Praha | I11: PetrNelhýbel | J11: petr.nelhybel@domansky.cz | K11: 778726674 | L11: Osobní | M11: Hyundai | N11: NE | O11: 7:00-19:00|7:00-19:00|7:00-19:00|7:00-19:00|7:00-19:00|8:00-14:00|-. | Q11: =VLOOKUP(G11,seznampsc!A:B,2,FALSE) -> Hlavní město Praha | R11: =VLOOKUP(G11,seznampsc!A:C,3,FALSE) -> Hlavní město Praha | S11: 50.039651 | T11: 14.328208 | AV11: 200000
A12: Ano | B12: ACC | C12: 119/2019 | D12: 75609878 | E12: AutoServisROVALIs.r.o. | F12: Gellhornova2491/2a | G12: 67801 | H12: Blansko | I12: LiborFojtík | J12: info@autoservis-rovali.cz | K12: 734243691 | L12: NeautorizovanýservisSAG | M12: všechnavozidla | N12: NE | O12: Po-Pá8:00-16:30 | Q12: =VLOOKUP(G12,seznampsc!A:B,2,FALSE) -> Blansko | R12: =VLOOKUP(G12,seznampsc!A:C,3,FALSE) -> Jihomoravský kraj | S12: 49.349991 | T12: 16.656527 | AD12: 680 | AE12: 680 | AF12: 680 | AQ12: 10 | AU12: dřívepodnázvemLiborHavlík/AutoservisHavlíks.r.o..PřejmenovánopodledatopdACCz09/2021. | AV12: 100000
B13: DIRECT | C13: 007/2016 | D13: 27182975 | E13: RCLoudaAuto | F13: Helsinská166/2 | G13: 15500 | H13: Praha | I13: VlastimilBrabec | J13: vlastimil.brabec@louda.cz | K13: 225340440 | L13: Osobní | M13: Renault,Dacia | N13: NE | O13: 7:30-18:00|7:30-18:00|7:30-18:00|7:30-18:00|7:30-18:00|-|-. | Q13: =VLOOKUP(G13,seznampsc!A:B,2,FALSE) -> Hlavní město Praha | R13: =VLOOKUP(G13,seznampsc!A:C,3,FALSE) -> Hlavní město Praha | S13: 50.050835 | T13: 14.291968 | AU13: Od.1.10.2022prodejpodLoudaAuto.PůvodnínázevRenaultRetailGroupCZ.Od1.5.2023fůzesLoudaAuto,převodpodsmlouvu266/2022. | AV13: 200000
B14: DIRECT | C14: 008/2016 | D14: 48030317 | E14: AUTODRUŽSTVOPRAHA | F14: Spojovací41/783 | G14: 19000 | H14: Praha | I14: LadislavTurek,MichaelWeiss | J14: kratochvil@adpraha.cz | K14: 7.2532199e+08 | L14: NeautorizovanýservisDIRECT | M14: všechnavozidla | N14: NE | O14: 7:00-17:30|7:00-17:30|7:00-17:30|7:00-17:30|7:00-17:30|-|-. | Q14: =VLOOKUP(G14,seznampsc!A:B,2,FALSE) -> Hlavní město Praha | R14: =VLOOKUP(G14,seznampsc!A:C,3,FALSE) -> Hlavní město Praha | S14: 50.097927 | T14: 14.49834 | AU14: Od1.9.2021jižneexistuje
A15: Ano | B15: DIRECT | C15: 009/2016 | D15: 24805327 | E15: KarosářCZ,s.r.o. | F15: Hoškovice22 | G15: 29501 | H15: MnichovoHradiště | I15: Příjemoprav | J15: info@karosar.cz | K15: 774847303 | L15: GaranceMobility | M15: Všechnavozidla | N15: NE | Q15: =VLOOKUP(G15,seznampsc!A:B,2,FALSE) -> Česká Lípa | R15: =VLOOKUP(G15,seznampsc!A:C,3,FALSE) -> Liberecký kraj | AD15: 740 | AE15: 740 | AF15: 740 | AJ15: 107 | AK15: 107 | AN15: 0.05 | AT15: 250 | AV15: 100000
A16: Ano | B16: DIRECT | C16: 009/2016 | D16: 24805327 | E16: KarosářCZ,s.r.o. | F16: Hoškovice22 | G16: 29501 | H16: MnichovoHradiště | I16: pí.Šulcová | J16: info@karosar.cz | K16: 774847303 | L16: PDRopravy | M16: všechnavozidla | N16: NE | O16: PO-NEDLEDOHODY | Q16: =VLOOKUP(G16,seznampsc!A:B,2,FALSE) -> Česká Lípa | R16: =VLOOKUP(G16,seznampsc!A:C,3,FALSE) -> Liberecký kraj | S16: 50.53111 | T16: 15.000214 | AD16: 740 | AE16: 740 | AF16: 740 | AJ16: 107 | AK16: 107 | AN16: 0.05 | AT16: 250 | AV16: 100000
A17: Ano | B17: DIRECT | C17: 009/2016 | D17: 24805327 | E17: KarosářCZ,s.r.o. | F17: Hoškovice22 | G17: 29501 | H17: MnichovoHradiště | I17: IrenaBenešová,DanaJanatová | J17: info@karosar.cz | K17: 7.748473e+08 | L17: PDRopravy | M17: všechnavozidla | N17: ANO | O17: PO-NEDLEDOHODY | Q17: =VLOOKUP(G17,seznampsc!A:B,2,FALSE) -> Česká Lípa | R17: =VLOOKUP(G17,seznampsc!A:C,3,FALSE) -> Liberecký kraj | S17: 50.53111 | T17: 15.000214 | AD17: 740 | AE17: 740 | AF17: 740 | AJ17: 107 | AK17: 107 | AN17: 0.05 | AT17: 250 | AU17: k1.2.2023zadanéprohlídkovémísto. | AV17: 100000
B18: DIRECT | C18: 010/2016 | D18: 60108151 | E18: HAVEX-autos.r.o. | F18: Jateční317/41 | G18: 17000 | H18: Praha | J18: ph.servis@havex.cz | K18: 257213830 | L18: Osobní | M18: Škoda | N18: NE | O18: 7:00-19:00|7:00-19:00|7:00-19:00|7:00-19:00|7:00-19:00|8:00-12:00|-. | Q18: =VLOOKUP(G18,seznampsc!A:B,2,FALSE) -> Hlavní město Praha | R18: =VLOOKUP(G18,seznampsc!A:C,3,FALSE) -> Hlavní město Praha | S18: 50.10058 | T18: 14.451692 | AV18: 200000
B19: DIRECT | C19: 010/2016 | D19: 60108151 | E19: HAVEX-autos.r.o. | F19: NaBělidle503 | G19: 54301 | H19: Vrchlabí | I19: OndřejŠulc | J19: david.neumann@havex.cz | K19: 499406314,499406312-313 | L19: Osobní | M19: Škoda,Fiat,Jeep,Citroen,Peugeot | N19: NE | O19: 7:00-17:00|7:00-17:00|7:00-17:00|7:00-17:00|7:00-17:00|8:00-12:00|-. | Q19: =VLOOKUP(G19,seznampsc!A:B,2,FALSE) -> Trutnov | R19: =VLOOKUP(G19,seznampsc!A:C,3,FALSE) -> Královéhradecký kraj | S19: 50.614686 | T19: 15.62534 | AV19: 200000
A20: Ano | B20: ACC | C20: 119/2019 | D20: 3635724 | E20: HUCARs.r.o. | F20: Nádražní85 | G20: 59301 | H20: BystřicenadPernštejnem | J20: hucar@email.cz | K20: 605146970 | L20: NeautorizovanýservisSAG | M20: všechnavozidla | N20: NE | O20: Po-Pá8:00-16:30 | Q20: =VLOOKUP(G20,seznampsc!A:B,2,FALSE) -> Blansko | R20: =VLOOKUP(G20,seznampsc!A:C,3,FALSE) -> Jihomoravský kraj | S20: 49.52094 | T20: 16.25925 | AD20: 680 | AE20: 680 | AF20: 680 | AQ20: 10 | AV20: 100000
B21: DIRECT | C21: 010/2016 | D21: 60108151 | E21: HAVEX-autos.r.o. | F21: Pražská1825 | G21: 50901 | H21: NováPaka | I21: PetrKmínek | J21: np.servis@havex.cz | K21: 493722124 | L21: Osobní | M21: Škoda,Seat,Cupra | N21: NE | O21: 7:00-17:00|7:00-17:00|7:00-17:00|7:00-17:00|7:00-17:00|8:00-11:00|-. | Q21: =VLOOKUP(G21,seznampsc!A:B,2,FALSE) -> Jičín | R21: =VLOOKUP(G21,seznampsc!A:C,3,FALSE) -> Královéhradecký kraj | S21: 50.483349 | T21: 15.505085 | AV21: 200000
B22: DIRECT | C22: 010/2016 | D22: 60108151 | E22: HAVEX-autos.r.o. | F22: PodČernýmmostem577 | G22: 51301 | H22: Semily | I22: OtakarHašek | J22: otakar.hasek@havex.cz,sm.servis@havex.cz | K22: 4.8162126e+08 | L22: Osobní | M22: Škoda | N22: NE | O22: 7:00-17:00|7:00-17:00|7:00-17:00|7:00-17:00|7:00-17:00|8:00-11:00|-. | Q22: =VLOOKUP(G22,seznampsc!A:B,2,FALSE) -> Semily | R22: =VLOOKUP(G22,seznampsc!A:C,3,FALSE) -> Liberecký kraj | S22: 50.608766 | T22: 15.322905 | AU22: Pobočkauzavřena,prodána. | AV22: 200000
B23: DIRECT | C23: 010/2016 | D23: 60108151 | E23: HAVEX-autos.r.o. | F23: Pražská782/IV | G23: 50351 | H23: ChlumecnadCidlinou | I23: MilošSenohrábek | J23: milos.senohrabek@havex.cz | K23: 7.315931e+08 | L23: Osobní | M23: Škoda,Seat,Cupra | N23: NE | O23: 7:00-17:00|7:00-17:00|7:00-17:00|7:00-17:00|7:00-17:00|8:00-11:00|-. | Q23: =VLOOKUP(G23,seznampsc!A:B,2,FALSE) -> Hradec Králové | R23: =VLOOKUP(G23,seznampsc!A:C,3,FALSE) -> Královéhradecký kraj | S23: 50.159819 | T23: 15.446799 | AV23: 200000
A24: Ano | B24: DIRECT | C24: 130/2019 | D24: 29249694 | E24: MMautoopravnas.r.o. | F24: Molenburk78 | G24: 67913 | H24: Vysočany | I24: MichalPřibyl | J24: MM.auto.opravy@seznam.cz | K24: 604359045 | L24: FérservisDIRECT | M24: všechnavozidla | N24: NE | O24: Po-Pá8:00-17:00 | Q24: =VLOOKUP(G24,seznampsc!A:B,2,FALSE) -> Blansko | R24: =VLOOKUP(G24,seznampsc!A:C,3,FALSE) -> Jihomoravský kraj | S24: 49.433516 | T24: 16.809472 | AD24: 680 | AE24: 680 | AF24: 680 | AJ24: 107 | AK24: 116 | AP24: 2.5 | AQ24: 10 | AS24: specpodmínky | AV24: 200000
A25: Ano | B25: DIRECT | C25: 011/2016 | D25: 60293713 | E25: LRAUTO-TomášLehnert | F25: Staříč541 | G25: 73943 | H25: Staříč | I25: MartinRojíček | J25: lrnehody@seznam.cz | K25: 604230992 | L25: NeautorizovanýservisDIRECT | M25: všechnavozidla+motocykly | N25: NE | O25: 8:30-17:00|8:30-17:00|8:30-17:00|8:30-17:00|8:30-17:00|-|-. | Q25: =VLOOKUP(G25,seznampsc!A:B,2,FALSE) -> Frýdek-Místek | R25: =VLOOKUP(G25,seznampsc!A:C,3,FALSE) -> Moravskoslezský kraj | S25: 49.688086 | T25: 18.305939 | AD25: 450 | AE25: 450 | AF25: 450 | AJ25: 120 | AK25: 120 | AO25: 0.03 | AT25: 250 | AV25: 50000
A26: Ano | B26: DIRECT | C26: 012/2016 | D26: 13093401 | E26: ZdeněkŘedina-Autoopravna | F26: náměstíKomenského31 | G26: 76362 | H26: Tlumačov | I26: ZděněkŘedina | J26: autoredina@volny.cz | K26: 604943621 | L26: NeautorizovanýservisDIRECT | M26: všechnavozidla | N26: NE | O26: 7:00-16:00|7:00-16:00|7:00-16:00|7:00-16:00|7:00-16:00|-|-. | Q26: =VLOOKUP(G26,seznampsc!A:B,2,FALSE) -> Zlín | R26: =VLOOKUP(G26,seznampsc!A:C,3,FALSE) -> Zlínský kraj | S26: 49.252863 | T26: 17.492868 | AD26: 600 | AE26: 600 | AF26: 600 | AJ26: 107 | AK26: 116 | AT26: 250 | AV26: 50000
B27: DIRECT | C27: 013/2016 | D27: 29128889 | E27: AutoSvárov.cz | F27: Kozákova3084 | G27: 47001 | H27: ČeskáLípa | I27: TomášKozák | J27: info@autosvarov.cz | K27: 777727073 | L27: NeautorizovanýservisDIRECT | M27: všechnavozidla | N27: NE | O27: 8:00-16:00|8:00-16:00|8:00-16:00|8:00-16:00|8:00-16:00|-|-. | Q27: =VLOOKUP(G27,seznampsc!A:B,2,FALSE) -> Česká Lípa | R27: =VLOOKUP(G27,seznampsc!A:C,3,FALSE) -> Liberecký kraj | S27: 50.679062 | T27: 14.532456 | AU27: Výpověďsmlouvyk30.11.2022.ZestranyDirectu.PL102022
B28: DIRECT | C28: 014/2016 | D28: 26946955 | E28: Daníček,s.r.o. | F28: Vizovická423 | G28: 76001 | H28: Zlín | I28: PetraKalbáčová | J28: kalbacova@autodanicek.cz | K28: 6.0273134e+08 | L28: Osobní | M28: Škoda | N28: NE | O28: 7:00-17:00|7:00-17:00|7:00-17:00|7:00-17:00|7:00-17:00|8:00-12:00|-. | Q28: =VLOOKUP(G28,seznampsc!A:B,2,FALSE) -> Zlín | R28: =VLOOKUP(G28,seznampsc!A:C,3,FALSE) -> Zlínský kraj | S28: 49.223678 | T28: 17.702229 | AU28: původníadresa:pojistovny@autodanicek.cz | AV28: 200000
A29: Ano | B29: DIRECT | C29: 015/2016 | D29: 61681857 | E29: MBSAUTOSLUŽBAMĚLNÍK | F29: Kamenická1995/4 | G29: 27601 | H29: Mělník | I29: StanislavHlaváček | J29: mbslakovna@seznam.cz | K29: 603578123 | L29: NeautorizovanýservisDIRECT | M29: všechnavozidla+nákladníaautobusy | N29: NE | O29: 8:00-16:30|8:00-16:30|8:00-16:30|8:00-16:30|8:00-16:30|-|-. | Q29: =VLOOKUP(G29,seznampsc!A:B,2,FALSE) -> Mělník | R29: =VLOOKUP(G29,seznampsc!A:C,3,FALSE) -> Středočeský kraj | S29: 50.352477 | T29: 14.49137 | U29: 0.05 | AA29: 5 | AB29: 500 | AC29: 500 | AD29: 600 | AE29: 600 | AF29: 650 | AG29: 800 | AH29: 800 | AI29: 800 | AJ29: 107 | AK29: 116 | AN29: 5 | AO29: 3 | AV29: 50000
B30: DIRECT | C30: 016/2016 | D30: 16907752 | E30: AUTOSIBŘINA | F30: VKorytech67 | G30: 10000 | H30: Praha | I30: MilanKarpíšek | J30: lakovna@autosibrina.cz | K30: 774520568 | L30: NeautorizovanýservisDIRECT | M30: všechnavozidla | N30: NE | O30: 8:00-17:00|8:00-17:00|8:00-17:00|8:00-17:00|8:00-17:00|-|-. | Q30: =VLOOKUP(G30,seznampsc!A:B,2,FALSE) -> Hlavní město Praha | R30: =VLOOKUP(G30,seznampsc!A:C,3,FALSE) -> Hlavní město Praha | S30: 50.064788 | T30: 14.491632 | AU30: V2023zněmanajinéIČKarpichCar11829800.Neprodlouženásmlouvaospolupráci.
B31: DIRECT | C31: 017/2016 | D31: 25869833 | E31: AUTOHÉGRa.s. | F31: Olomoucká110 | G31: 78501 | H31: Šternberk | I31: MartinSeidl,OldřichBeneš | J31: servis@stbk.auto-hegr.cz | K31: 585002024 | L31: Osobní | M31: Škoda,Volkswagen | N31: NE | O31: 6:30-21:00|6:30-21:00|6:30-21:00|6:30-21:00|6:30-21:00|7:00-12:00|-. | Q31: =VLOOKUP(G31,seznampsc!A:B,2,FALSE) -> Olomouc | R31: =VLOOKUP(G31,seznampsc!A:C,3,FALSE) -> Olomoucký kraj | S31: 49.709925 | T31: 17.291144 | AU31: K1.1.2024ukončeníspolupráce,výpověďznašístrany-vysokésazby.Od1.1.2022zdůvoduodmítnutídohodynanavýšenícenservisníchpracínebudemedoservisůsměrovataktivněklienty.Servisyjsoutakpouzevpasivníroli.Jižneníaut.servisAudi | AV31: 200000
B32: DIRECT | C32: 017/2016 | D32: 25869833 | E32: AUTOHÉGRa.s. | F32: Jesenická2839/1b | G32: 78701 | H32: Šumperk | I32: EvženStraka | J32: servis@sumperk.auto-hegr.cz | K32: 583301006 | L32: Osobní | M32: Škoda,Volkswagen | N32: NE | O32: 7:00-17:00|7:00-17:00|7:00-17:00|7:00-17:00|7:00-17:00|8:00-12:00|-. | Q32: =VLOOKUP(G32,seznampsc!A:B,2,FALSE) -> Šumperk | R32: =VLOOKUP(G32,seznampsc!A:C,3,FALSE) -> Olomoucký kraj | S32: 49.955517 | T32: 16.965991 | AU32: K1.1.2024ukončeníspolupráce,výpověďznašístrany-vysokésazby.Od1.1.2022zdůvoduodmítnutídohodynanavýšenícenservisníchpracínebudemedoservisůsměrovataktivněklienty.Servisyjsoutakpouzevpasivníroli.Jižneníaut.servisAudi | AV32: 200000
B33: DIRECT | C33: 017/2016 | D33: 25869833 | E33: AUTOHÉGRa.s. | F33: Hněvotínská568/54a | G33: 77900 | H33: Olomouc | I33: TomášBejdák | J33: tomas.bejdak@auto-hegr.cz,servis@auto-hegr.cz | K33: 585758323 | L33: Osobní | M33: Škoda,Volkswagen | N33: NE | O33: 6:30-21:00|6:30-21:00|6:30-21:00|6:30-21:00|6:30-21:00|7:00-12:00|-. | Q33: =VLOOKUP(G33,seznampsc!A:B,2,FALSE) -> Olomouc | R33: =VLOOKUP(G33,seznampsc!A:C,3,FALSE) -> Olomoucký kraj | S33: 49.5887 | T33: 17.240435 | AU33: K1.1.2024ukončeníspolupráce,výpověďznašístrany-vysokésazby.Od1.1.2022zdůvoduodmítnutídohodynanavýšenícenservisníchpracínebudemedoservisůsměrovataktivněklienty.Servisyjsoutakpouzevpasivníroli.Jižneníaut.servisAudi | AV33: 200000
A34: Ano | B34: DIRECT | C34: 018/2016 | D34: 26933209 | E34: AUTOPOSPÍŠIL | F34: Karlova27 | G34: 61400 | H34: Brno | I34: MartinŠob,PetraMalantová | J34: martin@autopospisil.cz,pojistneudalosti@autopospisil.cz | K34: 6.0527923e+08 | L34: NeautorizovanýservisDIRECT | M34: všechnavozidla | N34: NE | O34: Dledohody | Q34: =VLOOKUP(G34,seznampsc!A:B,2,FALSE) -> Brno-město | R34: =VLOOKUP(G34,seznampsc!A:C,3,FALSE) -> Jihomoravský kraj | S34: 49.212807 | T34: 16.643693 | AD34: 450 | AE34: 550 | AF34: 550 | AJ34: 120 | AK34: 130 | AO34: 3 | AV34: 100000
B35: DIRECT | C35: 019/2016 | D35: 25329677 | E35: AUTODOBROVOLNÝV.M.s.r.o. | F35: Fr.Stránecké1330/2 | G35: 59401 | H35: VelkéMeziříčí | I35: ZdeněkŠoukal | J35: karosarna.vm@autodobrovolny.cz | K35: 5.6650235e+08 | L35: Osobní | M35: Opel,Chevrolet,Škoda | N35: NE | O35: 7:30-17:00|7:30-17:00|7:30-17:00|7:30-17:00|7:30-17:00|8:00-12:00|-. | Q35: =VLOOKUP(G35,seznampsc!A:B,2,FALSE) -> Žďár nad Sázavou | R35: =VLOOKUP(G35,seznampsc!A:C,3,FALSE) -> Kraj Vysočina | S35: 49.358718 | T35: 15.996223 | AV35: 200000
B36: DIRECT | C36: 019/2016 | D36: 25329677 | E36: AUTODOBROVOLNÝV.M.s.r.o. | F36: Okružní4720/3 | G36: 58601 | H36: Jihlava | I36: VladimírLacek | J36: servis.ji@autodobrovolny.cz | K36: 5.6757972e+08 | L36: Osobní | M36: Opel,Chevrolet,Škoda | N36: NE | O36: 7:30-17:00|7:30-17:00|7:30-17:00|7:30-17:00|7:30-17:00|8:00-12:00|-. | Q36: =VLOOKUP(G36,seznampsc!A:B,2,FALSE) -> Jihlava | R36: =VLOOKUP(G36,seznampsc!A:C,3,FALSE) -> Kraj Vysočina | S36: 49.405832 | T36: 15.594249 | AV36: 200000
B37: DIRECT | C37: 019/2016 | D37: 25329677 | E37: AUTODOBROVOLNÝV.M.sro | F37: Oblekovice395 | G37: 66902 | H37: Znojmo | I37: PetrLodes | J37: servis.zn@autodobrovolny.cz | K37: 515200402 | L37: Osobní | M37: Opel,Chevrolet,Škoda | N37: NE | O37: 7:00-16:30|7:00-16:30|7:00-16:30|7:00-16:30|7:00-16:30|8:00-12:00|-. | Q37: =VLOOKUP(G37,seznampsc!A:B,2,FALSE) -> Znojmo | R37: =VLOOKUP(G37,seznampsc!A:C,3,FALSE) -> Jihomoravský kraj | S37: 48.831113 | T37: 16.07111 | AV37: 200000
A38: Ano | B38: DIRECT | C38: 020/2017 | D38: 62587536 | E38: AUTOPLUSPrahas.r.o. | F38: Kyslíková1984/4 | G38: 14300 | H38: Praha4 | J38: info@autoplus-praha.cz | K38: 602313844 | L38: NeautorizovanýservisDIRECT | M38: všechnavozidla+nákladnívozidla | N38: NE | O38: 8:00-17:00|8:00-17:00|8:00-17:00|8:00-17:00|8:00-17:00|-|-. | Q38: =VLOOKUP(G38,seznampsc!A:B,2,FALSE) -> Hlavní město Praha | R38: =VLOOKUP(G38,seznampsc!A:C,3,FALSE) -> Hlavní město Praha | S38: 49.9914056 | T38: 14.4110006 | AD38: 743 | AE38: 743 | AF38: 743 | AJ38: 107 | AK38: 116 | AN38: 0.05 | AT38: 250 | AV38: 50000
B39: DIRECT | C39: 021/2016 | D39: 46969730 | E39: HoráckéAutodružstvoVM | F39: KNovémunádraží1345 | G39: 59401 | H39: VelkéMeziříčí | I39: MartinHabán | J39: haban@horacke-vm.cz | K39: 608666318 | L39: Osobní | M39: Škoda | N39: NE | O39: 7:00-17:00|7:00-17:00|7:00-17:00|7:00-17:00|7:00-17:00|-|-. | Q39: =VLOOKUP(G39,seznampsc!A:B,2,FALSE) -> Žďár nad Sázavou | R39: =VLOOKUP(G39,seznampsc!A:C,3,FALSE) -> Kraj Vysočina | S39: 49.35005 | T39: 16.021148 | AV39: 200000
B40: DIRECT | C40: 022/2016 | D40: 49903748 | E40: KHKŽatecs.r.o. | F40: Čeradická2031 | G40: 43801 | H40: Žatec | I40: NikolaRayman | J40: servis@khkzatec.cz | K40: 6.022123e+08 | L40: Osobní | M40: Peugeot | N40: NE | O40: 7:00-17:00|7:00-17:00|7:00-17:00|7:00-17:00|7:00-17:00|-|-. | Q40: =VLOOKUP(G40,seznampsc!A:B,2,FALSE) -> Louny | R40: =VLOOKUP(G40,seznampsc!A:C,3,FALSE) -> Ústecký kraj | S40: 50.3187242 | T40: 13.5299128 | AV40: 200000
...

Sheet seznampsc
A1: PSC | B1: okres | C1: kraj
A2: 10000 | B2: Hlavní město Praha | C2: Hlavní město Praha
A3: 10100 | B3: Hlavní město Praha | C3: Hlavní město Praha
A4: 10200 | B4: Hlavní město Praha | C4: Hlavní město Praha
A5: 10300 | B5: Hlavní město Praha | C5: Hlavní město Praha
A6: 10400 | B6: Hlavní město Praha | C6: Hlavní město Praha
A7: 10600 | B7: Hlavní město Praha | C7: Hlavní město Praha
A8: 10700 | B8: Hlavní město Praha | C8: Hlavní město Praha
A9: 10800 | B9: Hlavní město Praha | C9: Hlavní město Praha
A10: 10900 | B10: Hlavní město Praha | C10: Hlavní město Praha
A11: 11000 | B11: Hlavní město Praha | C11: Hlavní město Praha
A12: 11800 | B12: Hlavní město Praha | C12: Hlavní město Praha
A13: 11900 | B13: Hlavní město Praha | C13: Hlavní město Praha
... A2705: 79862 | B2705: Prostějov | C2705: Olomoucký kraj
